Workbook

Sheet Previsão CX
A1: Código | B1: Descrição do Produto | C1: BU | D1: Categoria | E1: Segmento | F1: ABC | G1: Grupo Produto | H1: jan/23 | I1: fev/23 | J1: mar/23 | K1: abr/23 | L1: mai/23 | M1: jun/23 | N1: jul/23 | O1: ago/23 | P1: set/23 | Q1: out/23 | R1: nov/23 | S1: dez/23 | T1: jan/24 | U1: fev/24 | V1: mar/24 | W1: abr/24 | X1: mai/24 | Y1: jun/24 | Z1: jul/24 | AA1: ago/24 | AB1: set/24 | AC1: out/24 | AD1: nov/24 | AE1: dez/24 | AF1: jan/25 | AG1: fev/25 | AH1: mar/25 | AI1: abr/25 | AJ1: mai/25 | AK1: jun/25 | AL1: jul/25 | AM1: ago/25 | AN1: set/25 | AO1: out/25 | AP1: nov/25 | AQ1: dez/25 | AR1: jan/26 | AS1: fev/26 | AT1: mar/26 | AU1: abr/26 | AV1: mai/26
A2: 410015729 | B2: LINEA ADOC SACARINA LIQ 12X100ML | C2: =IFERROR(VLOOKUP(Tabela1[[#This Row],[Código]],Cadastro!$A:$J,2,0),"Sem Cadastro") -> ADOÇANTES | D2: =IFERROR(VLOOKUP(Tabela1[[#This Row],[Código]],Cadastro!$A:$J,3,0),"Sem Cadastro") -> SACARINA | E2: =IFERROR(VLOOKUP(Tabela1[[#This Row],[Código]],Cadastro!$A:$J,4,0),"Sem Cadastro") -> SACARINA LÍQUIDO | F2: =IFERROR(VLOOKUP(Tabela1[[#This Row],[Código]],Cadastro!$A:$J,5,0),"Sem Cadastro") -> LANÇAMENTO | G2: LIQUIDO SACARINA | H2: 0 | I2: 0 | J2: 0 | K2: 0 | L2: 0 | M2: 0 | N2: 0 | O2: 0 | P2: 0 | Q2: 0 | R2: 0 | S2: 0 | T2: 0 | U2: 0 | V2: 0 | W2: 0 | X2: 0 | Y2: 0 | Z2: 0 | AA2: 0 | AB2: 0 | AC2: 0 | AD2: 0 | AE2: 0 | AF2: 0 | AG2: 0 | AH2: 0 | AI2: 0 | AJ2: 0 | AK2: 0 | AL2: 0 | AM2: 0 | AN2: 0 | AO2: 0 | AP2: 0 | AQ2: 0 | AR2: 0 | AS2: 0 | AT2: 10000 | AU2: 30000 | AV2: 30000
A3: 410025614 | B3: LINEA ADOC SUCRAL INSTIT 1000X0,5G | C3: =IFERROR(VLOOKUP(Tabela1[[#This Row],[Código]],Cadastro!$A:$J,2,0),"Sem Cadastro") -> ADOÇANTES | D3: =IFERROR(VLOOKUP(Tabela1[[#This Row],[Código]],Cadastro!$A:$J,3,0),"Sem Cadastro") -> SUCRALOSE | E3: =IFERROR(VLOOKUP(Tabela1[[#This Row],[Código]],Cadastro!$A:$J,4,0),"Sem Cadastro") -> SUCRALOSE INSTITUCIONAL | F3: =IFERROR(VLOOKUP(Tabela1[[#This Row],[Código]],Cadastro!$A:$J,5,0),"Sem Cadastro") -> AA | G3: PO LINEA | H3: 0 | I3: 0 | J3: 0 | K3: 2738 | L3: 15267.918 | M3: 11000 | N3: 13380 | O3: 11200 | P3: 0 | Q3: 0 | R3: 0 | S3: 0 | T3: 0 | U3: 0 | V3: 8000 | W3: 9000 | X3: 10500 | Y3: 10300 | Z3: 13664 | AA3: 13664 | AB3: 12000 | AC3: 13061 | AD3: 12500 | AE3: 12000 | AF3: 12848 | AG3: 11640.715 | AH3: 12500 | AI3: 13000 | AJ3: 16654.809 | AK3: 14091.489 | AL3: 16148.482 | AM3: 13021.199 | AN3: 13842.103 | AO3: 15007.387 | AP3: 13784.536 | AQ3: 12418.651 | AR3: 11986 | AS3: 13270 | AT3: 2500 | AU3: 2000 | AV3: 12000
A4: 410014792 | B4: LINEA ADOC STEVIA LIQ 12X60ML | C4: =IFERROR(VLOOKUP(Tabela1[[#This Row],[Código]],Cadastro!$A:$J,2,0),"Sem Cadastro") -> ADOÇANTES | D4: =IFERROR(VLOOKUP(Tabela1[[#This Row],[Código]],Cadastro!$A:$J,3,0),"Sem Cadastro") -> STEVIA | E4: =IFERROR(VLOOKUP(Tabela1[[#This Row],[Código]],Cadastro!$A:$J,4,0),"Sem Cadastro") -> STEVIA LÍQUIDO | F4: =IFERROR(VLOOKUP(Tabela1[[#This Row],[Código]],Cadastro!$A:$J,5,0),"Sem Cadastro") -> AA | G4: LIQUIDO STEVIA | H4: 5960.0875 | I4: 11308.147 | J4: 9995.0983 | K4: 9931 | L4: 10702.787 | M4: 10000 | N4: 11150 | O4: 10000 | P4: 11200 | Q4: 10200 | R4: 9548.2961 | S4: 7966 | T4: 7000 | U4: 8500 | V4: 10792.28 | W4: 10500 | X4: 9800 | Y4: 10500 | Z4: 11133 | AA4: 11133 | AB4: 9500 | AC4: 9900 | AD4: 9000 | AE4: 7500 | AF4: 7495 | AG4: 8726.2535 | AH4: 8861.8104 | AI4: 8400 | AJ4: 8348.373 | AK4: 9353.2699 | AL4: 10543.179 | AM4: 10401.859 | AN4: 9835.8115 | AO4: 9638.7217 | AP4: 11849.785 | AQ4: 9921.5009 | AR4: 8465 | AS4: 11000 | AT4: 3169.8 | AU4: 3045.6 | AV4: 9170
A5: 410010021 | B5: LINEA ADOC SUCRAL LIQ 24X75ML | C5: =IFERROR(VLOOKUP(Tabela1[[#This Row],[Código]],Cadastro!$A:$J,2,0),"Sem Cadastro") -> ADOÇANTES | D5: =IFERROR(VLOOKUP(Tabela1[[#This Row],[Código]],Cadastro!$A:$J,3,0),"Sem Cadastro") -> SUCRALOSE | E5: =IFERROR(VLOOKUP(Tabela1[[#This Row],[Código]],Cadastro!$A:$J,4,0),"Sem Cadastro") -> SUCRALOSE LÍQUIDO | F5: =IFERROR(VLOOKUP(Tabela1[[#This Row],[Código]],Cadastro!$A:$J,5,0),"Sem Cadastro") -> AA | G5: LIQUIDO LINEA | H5: 6872.7389 | I5: 10157.4 | J5: 9211.3862 | K5: 10828 | L5: 10835.167 | M5: 10800 | N5: 10000 | O5: 9600 | P5: 11000 | Q5: 10000 | R5: 10416.323 | S5: 7716 | T5: 6000 | U5: 7500 | V5: 9500 | W5: 9149.1294 | X5: 9000 | Y5: 10000 | Z5: 9542 | AA5: 9542 | AB5: 8400 | AC5: 7833 | AD5: 8000 | AE5: 7800 | AF5: 8031 | AG5: 7430.0377 | AH5: 8000 | AI5: 8000 | AJ5: 7739.2287 | AK5: 8524.7987 | AL5: 9573.6173 | AM5: 10168.038 | AN5: 10262.676 | AO5: 9986.2415 | AP5: 9443.4565 | AQ5: 9225.6649 | AR5: 7568 | AS5: 8460 | AT5: 1800 | AU5: 2000 | AV5: 7560
A6: 415014749 | B6: LINEA ADOC STEVIA LIQ (50% DESC 2ª UNID) 60ML | C6: =IFERROR(VLOOKUP(Tabela1[[#This Row],[Código]],Cadastro!$A:$J,2,0),"Sem Cadastro") -> ADOÇANTES | D6: =IFERROR(VLOOKUP(Tabela1[[#This Row],[Código]],Cadastro!$A:$J,3,0),"Sem Cadastro") -> STEVIA | E6: =IFERROR(VLOOKUP(Tabela1[[#This Row],[Código]],Cadastro!$A:$J,4,0),"Sem Cadastro") -> STEVIA LÍQUIDO | F6: =IFERROR(VLOOKUP(Tabela1[[#This Row],[Código]],Cadastro!$A:$J,5,0),"Sem Cadastro") -> AA | G6: LIQUIDO STEVIA | H6: 2746 | I6: 3049.625 | J6: 2329.123 | K6: 2453 | L6: 4539.0566 | M6: 5000 | N6: 7360 | O6: 5500 | P6: 6500 | Q6: 5600 | R6: 5815.7803 | S6: 4624 | T6: 4500 | U6: 5000 | V6: 5637.39 | W6: 6000 | X6: 6000 | Y6: 6600 | Z6: 7581 | AA6: 7581 | AB6: 6500 | AC6: 5845 | AD6: 6000 | AE6: 4500 | AF6: 4819 | AG6: 6217.5333 | AH6: 6415.5439 | AI6: 6600 | AJ6: 5986.3211 | AK6: 6805.0418 | AL6: 8747.4706 | AM6: 8438.1987 | AN6: 7903.2551 | AO6: 8554.565 | AP6: 8541.5775 | AQ6: 7472.6794 | AR6: 7016 | AS6: 7925 | AT6: 8729 | AU6: 8810 | AV6: 9500
A7: 410040157 | B7: LINEA GELEIA MORANGO 12X230G | C7: =IFERROR(VLOOKUP(Tabela1[[#This Row],[Código]],Cadastro!$A:$J,2,0),"Sem Cadastro") -> ALIMENTOS | D7: =IFERROR(VLOOKUP(Tabela1[[#This Row],[Código]],Cadastro!$A:$J,3,0),"Sem Cadastro") -> GELEIAS | E7: =IFERROR(VLOOKUP(Tabela1[[#This Row],[Código]],Cadastro!$A:$J,4,0),"Sem Cadastro") -> GELEIA DE FRUTAS | F7: =IFERROR(VLOOKUP(Tabela1[[#This Row],[Código]],Cadastro!$A:$J,5,0),"Sem Cadastro") -> AA | G7: GELEIA LINEA | H7: 4374.4851 | I7: 5447.9532 | J7: 6444.0147 | K7: 6764 | L7: 5874.9995 | M7: 8580 | N7: 9400 | O7: 9600 | P7: 9540.8978 | Q7: 11200 | R7: 11500 | S7: 8644 | T7: 8000 | U7: 10000 | V7: 10339.33 | W7: 10000 | X7: 9000 | Y7: 9000 | Z7: 7686 | AA7: 7686 | AB7: 8000 | AC7: 7805 | AD7: 8000 | AE7: 6600 | AF7: 5889 | AG7: 5805.2255 | AH7: 6900 | AI7: 5800 | AJ7: 6040.0094 | AK7: 6304.6019 | AL7: 6105.4384 | AM7: 5492.9607 | AN7: 6216.8949 | AO7: 6927.4199 | AP7: 6698.6085 | AQ7: 5974.5126 | AR7: 5241 | AS7: 6500 | AT7: 7200 | AU7: 6900 | AV7: 7000
A8: 415015602 | B8: LINEA ADOC SUCRAL LIQ (50% DESC 2ª UNID) 75ML | C8: =IFERROR(VLOOKUP(Tabela1[[#This Row],[Código]],Cadastro!$A:$J,2,0),"Sem Cadastro") -> ADOÇANTES | D8: =IFERROR(VLOOKUP(Tabela1[[#This Row],[Código]],Cadastro!$A:$J,3,0),"Sem Cadastro") -> SUCRALOSE | E8: =IFERROR(VLOOKUP(Tabela1[[#This Row],[Código]],Cadastro!$A:$J,4,0),"Sem Cadastro") -> SUCRALOSE LÍQUIDO | F8: =IFERROR(VLOOKUP(Tabela1[[#This Row],[Código]],Cadastro!$A:$J,5,0),"Sem Cadastro") -> AA | G8: LIQUIDO LINEA | H8: 3661 | I8: 3174.1083 | J8: 1950.0214 | K8: 2984 | L8: 5939.0838 | M8: 6000 | N8: 10000 | O8: 6750 | P8: 8000 | Q8: 8500 | R8: 7812.2422 | S8: 6554 | T8: 4500 | U8: 5200 | V8: 8000 | W8: 7500 | X8: 7200 | Y8: 7700 | Z8: 8161 | AA8: 8161 | AB8: 7000 | AC8: 6854 | AD8: 7500 | AE8: 5750 | AF8: 5354 | AG8: 6244.4452 | AH8: 6443.3128 | AI8: 6363.7658 | AJ8: 5897.4838 | AK8: 6400.53 | AL8: 7298.9529 | AM8: 7743.1539 | AN8: 7431.5179 | AO8: 6850.0821 | AP8: 6969.5463 | AQ8: 5426.3213 | AR8: 6472 | AS8: 7228 | AT8: 7854 | AU8: 7727 | AV8: 8268
A9: 410014791 | B9: LINEA ADOC STEVIA LIQ 12X25ML | C9: =IFERROR(VLOOKUP(Tabela1[[#This Row],[Código]],Cadastro!$A:$J,2,0),"Sem Cadastro") -> ADOÇANTES | D9: =IFERROR(VLOOKUP(Tabela1[[#This Row],[Código]],Cadastro!$A:$J,3,0),"Sem Cadastro") -> STEVIA | E9: =IFERROR(VLOOKUP(Tabela1[[#This Row],[Código]],Cadastro!$A:$J,4,0),"Sem Cadastro") -> STEVIA LÍQUIDO | F9: =IFERROR(VLOOKUP(Tabela1[[#This Row],[Código]],Cadastro!$A:$J,5,0),"Sem Cadastro") -> AA | G9: LIQUIDO STEVIA | H9: 2751.4907 | I9: 4747.7538 | J9: 4051.9667 | K9: 3422 | L9: 4711.5528 | M9: 4400 | N9: 5130 | O9: 5000 | P9: 5800 | Q9: 5329.5239 | R9: 5208.1615 | S9: 3393 | T9: 3500 | U9: 4000 | V9: 5151.74 | W9: 5000 | X9: 4600 | Y9: 4200 | Z9: 4911 | AA9: 4911 | AB9: 4500 | AC9: 4600 | AD9: 4800 | AE9: 3500 | AF9: 4070 | AG9: 4295.6253 | AH9: 4444.6687 | AI9: 4650 | AJ9: 4801.3435 | AK9: 5421.7751 | AL9: 6168.8323 | AM9: 5963.1699 | AN9: 5893.9739 | AO9: 4966.1316 | AP9: 6387.3988 | AQ9: 4940.3444 | AR9: 4767 | AS9: 5316 | AT9: 5717 | AU9: 6600 | AV9: 7000
A10: 410250135 | B10: LINEA GELATINA MORANGO 24X10G | C10: =IFERROR(VLOOKUP(Tabela1[[#This Row],[Código]],Cadastro!$A:$J,2,0),"Sem Cadastro") -> ALIMENTOS | D10: =IFERROR(VLOOKUP(Tabela1[[#This Row],[Código]],Cadastro!$A:$J,3,0),"Sem Cadastro") -> SOBREMESAS EM PÓ | E10: =IFERROR(VLOOKUP(Tabela1[[#This Row],[Código]],Cadastro!$A:$J,4,0),"Sem Cadastro") -> GELATINA | F10: =IFERROR(VLOOKUP(Tabela1[[#This Row],[Código]],Cadastro!$A:$J,5,0),"Sem Cadastro") -> AA | G10: GELATINA LINEA | H10: 2101.3809 | I10: 2591.927 | J10: 2200.3469 | K10: 2415 | L10: 1303.7503 | M10: 2230 | N10: 3200 | O10: 3000 | P10: 3500 | Q10: 3675.5337 | R10: 3038.0942 | S10: 2617 | T10: 4000 | U10: 3400 | V10: 3644.15 | W10: 4000 | X10: 4000 | Y10: 4000 | Z10: 4240 | AA10: 4240 | AB10: 3850 | AC10: 3231 | AD10: 3000 | AE10: 2700 | AF10: 3855 | AG10: 3591.8081 | AH10: 4050 | AI10: 5100 | AJ10: 6040.3177 | AK10: 6297.2956 | AL10: 3446.7585 | AM10: 5665.6721 | AN10: 6235.5345 | AO10: 5184.4499 | AP10: 5504.7362 | AQ10: 5543.1689 | AR10: 4925 | AS10: 4000 | AT10: 6000 | AU10: 3787.355 | AV10: 5400
A11: 410025615 | B11: LINEA ADOC SUCRAL INSTIT 500X0,5G | C11: =IFERROR(VLOOKUP(Tabela1[[#This Row],[Código]],Cadastro!$A:$J,2,0),"Sem Cadastro") -> ADOÇANTES | D11: =IFERROR(VLOOKUP(Tabela1[[#This Row],[Código]],Cadastro!$A:$J,3,0),"Sem Cadastro") -> SUCRALOSE | E11: =IFERROR(VLOOKUP(Tabela1[[#This Row],[Código]],Cadastro!$A:$J,4,0),"Sem Cadastro") -> SUCRALOSE INSTITUCIONAL | F11: =IFERROR(VLOOKUP(Tabela1[[#This Row],[Código]],Cadastro!$A:$J,5,0),"Sem Cadastro") -> AB | G11: PO LINEA | H11: 0 | I11: 0 | J11: 0 | K11: 0 | L11: 0 | M11: 3323 | N11: 6700 | O11: 5500 | P11: 0 | Q11: 0 | R11: 0 | S11: 0 | T11: 0 | U11: 0 | V11: 6000 | W11: 6000 | X11: 6400 | Y11: 5300 | Z11: 6550 | AA11: 6550 | AB11: 4800 | AC11: 4896 | AD11: 4900 | AE11: 4800 | AF11: 3748 | AG11: 4460.8536 | AH11: 4400 | AI11: 4100 | AJ11: 4296.8383 | AK11: 4656.8007 | AL11: 4774.9307 | AM11: 5600.6801 | AN11: 5610.5375 | AO11: 7301.7642 | AP11: 8352.2804 | AQ11: 7507.0301 | AR11: 4259 | AS11: 4817 | AT11: 5608 | AU11: 3800 | AV11: 5500
A12: 400010032 | B12: LINEA ADOC SUCRAL LIQ PCK (2 75ML+1 25ML)X11 | C12: =IFERROR(VLOOKUP(Tabela1[[#This Row],[Código]],Cadastro!$A:$J,2,0),"Sem Cadastro") -> ADOÇANTES | D12: =IFERROR(VLOOKUP(Tabela1[[#This Row],[Código]],Cadastro!$A:$J,3,0),"Sem Cadastro") -> SUCRALOSE | E12: =IFERROR(VLOOKUP(Tabela1[[#This Row],[Código]],Cadastro!$A:$J,4,0),"Sem Cadastro") -> SUCRALOSE LÍQUIDO | F12: =IFERROR(VLOOKUP(Tabela1[[#This Row],[Código]],Cadastro!$A:$J,5,0),"Sem Cadastro") -> AA | G12: LIQUIDO LINEA | H12: 3844 | I12: 5824.475 | J12: 6678.0871 | K12: 5792 | L12: 8358.042 | M12: 4864 | N12: 6690 | O12: 5500 | P12: 6000 | Q12: 5600 | R12: 5642.175 | S12: 4856 | T12: 3500 | U12: 3500 | V12: 4000 | W12: 4295.3167 | X12: 4500 | Y12: 6550 | Z12: 6688 | AA12: 6688 | AB12: 6800 | AC12: 5875 | AD12: 5875 | AE12: 4000 | AF12: 3748 | AG12: 4803.134 | AH12: 4200 | AI12: 3500 | AJ12: 1697.011 | AK12: 3613.2024 | AL12: 3991.6435 | AM12: 4219.9203 | AN12: 4134.7541 | AO12: 4229.9692 | AP12: 4291.4269 | AQ12: 4062.2898 | AR12: 3551 | AS12: 4160 | AT12: 4764 | AU12: 4819 | AV12: 5200
A13: 410026410 | B13: LINEA ADOC STEVIA PO 12X50X0,5G | C13: =IFERROR(VLOOKUP(Tabela1[[#This Row],[Código]],Cadastro!$A:$J,2,0),"Sem Cadastro") -> ADOÇANTES | D13: =IFERROR(VLOOKUP(Tabela1[[#This Row],[Código]],Cadastro!$A:$J,3,0),"Sem Cadastro") -> STEVIA | E13: =IFERROR(VLOOKUP(Tabela1[[#This Row],[Código]],Cadastro!$A:$J,4,0),"Sem Cadastro") -> STEVIA PÓ | F13: =IFERROR(VLOOKUP(Tabela1[[#This Row],[Código]],Cadastro!$A:$J,5,0),"Sem Cadastro") -> AA | G13: PO STEVIA | H13: 0 | I13: 0 | J13: 0 | K13: 0 | L13: 0 | M13: 0 | N13: 0 | O13: 0 | P13: 3700 | Q13: 3675.5337 | R13: 3906.1211 | S13: 3142 | T13: 2700 | U13: 3000 | V13: 3800 | W13: 3800 | X13: 3600 | Y13: 3700 | Z13: 3958 | AA13: 3958 | AB13: 3700 | AC13: 3826 | AD13: 3900 | AE13: 2500 | AF13: 3213 | AG13: 3254.4384 | AH13: 3357.0304 | AI13: 3400 | AJ13: 3296.623 | AK13: 3507.6171 | AL13: 3953.6956 | AM13: 3979.5559 | AN13: 3784.6397 | AO13: 4434.7024 | AP13: 4514.9012 | AQ13: 4073.9741 | AR13: 3222 | AS13: 3611 | AT13: 1211.1 | AU13: 1155.6 | AV13: 3360
... A74: 410361087 | B74: LINEA MIST BOLO LARANJ 8X300G | C74: =IFERROR(VLOOKUP(Tabela1[[#This Row],[Código]],Cadastro!$A:$J,2,0),"Sem Cadastro") -> ALIMENTOS | D74: =IFERROR(VLOOKUP(Tabela1[[#This Row],[Código]],Cadastro!$A:$J,3,0),"Sem Cadastro") -> SOBREMESAS EM PÓ | E74: =IFERROR(VLOOKUP(Tabela1[[#This Row],[Código]],Cadastro!$A:$J,4,0),"Sem Cadastro") -> MISTURA PARA BOLO | F74: =IFERROR(VLOOKUP(Tabela1[[#This Row],[Código]],Cadastro!$A:$J,5,0),"Sem Cadastro") -> CC | G74: MISTURA PARA BOLO LINEA | H74: 503.38889 | I74: 575.53141 | J74: 474.27287 | K74: 523 | L74: 784.25592 | M74: 475 | N74: 412.83333 | O74: 500 | P74: 550 | Q74: 597.27423 | R74: 564.2175 | S74: 478 | T74: 400 | U74: 525 | V74: 649.6 | W74: 600 | X74: 500 | Y74: 425 | Z74: 543 | AA74: 543 | AB74: 400 | AC74: 378 | AD74: 348 | AE74: 280 | AF74: 268 | AG74: 324.93085 | AH74: 346.13744 | AI74: 290 | AJ74: 312.00702 | AK74: 312.43654 | AL74: 362.14771 | AM74: 296.81298 | AN74: 331.26866 | AO74: 280.51207 | AP74: 264.97772 | AQ74: 213.35796 | AR74: 318 | AS74: 379 | AT74: 315 | AU74: 250 | AV74: 300
A75: 410015602 | B75: ADOC LIQUIDO LINEA 12X2X75ML | C75: =IFERROR(VLOOKUP(Tabela1[[#This Row],[Código]],Cadastro!$A:$J,2,0),"Sem Cadastro") -> ADOÇANTES | D75: =IFERROR(VLOOKUP(Tabela1[[#This Row],[Código]],Cadastro!$A:$J,3,0),"Sem Cadastro") -> SUCRALOSE | E75: =IFERROR(VLOOKUP(Tabela1[[#This Row],[Código]],Cadastro!$A:$J,4,0),"Sem Cadastro") -> SUCRALOSE LÍQUIDO | F75: CC | G75: LIQUIDO LINEA | H75: 183 | I75: 0 | J75: 0 | K75: 0 | L75: 0 | M75: 0 | N75: 0 | O75: 0 | P75: 0 | Q75: 0 | R75: 0 | S75: 0 | T75: 0 | U75: 0 | V75: 0 | W75: 0 | X75: 0 | Y75: 0 | Z75: 0 | AA75: 0 | AB75: 0 | AC75: 0 | AD75: 0 | AE75: 0 | AF75: 0 | AG75: 0 | AH75: 0 | AI75: 0 | AJ75: 0 | AK75: 0 | AL75: 0 | AM75: 0 | AN75: 0 | AO75: 0 | AP75: 0 | AQ75: 0 | AR75: 0 | AS75: 0 | AT75: 0 | AU75: 0 | AV75: 0
A76: 410316664 | B76: LINEA CHOCOLATE BRANCO ZERO LACT 4X15X30G | C76: =IFERROR(VLOOKUP(Tabela1[[#This Row],[Código]],Cadastro!$A:$J,2,0),"Sem Cadastro") -> ALIMENTOS | D76: =IFERROR(VLOOKUP(Tabela1[[#This Row],[Código]],Cadastro!$A:$J,3,0),"Sem Cadastro") -> CHOCOLATES | E76: =IFERROR(VLOOKUP(Tabela1[[#This Row],[Código]],Cadastro!$A:$J,4,0),"Sem Cadastro") -> IMPULSO | F76: =IFERROR(VLOOKUP(Tabela1[[#This Row],[Código]],Cadastro!$A:$J,5,0),"Sem Cadastro") -> BB | G76: CHOCOLATE LINEA | H76: 367 | I76: 678.1146 | J76: 471.49586 | K76: 259 | L76: 51.147125 | M76: 354 | N76: 450 | O76: 322.8 | P76: 350 | Q76: 321.6092 | R76: 303.80942 | S76: 282 | T76: 0 | U76: 350 | V76: 0 | W76: 400 | X76: 400 | Y76: 450 | Z76: 354 | AA76: 354 | AB76: 300 | AC76: 294 | AD76: 300 | AE76: 250 | AF76: 242 | AG76: 259.61331 | AH76: 273 | AI76: 250 | AJ76: 210.24115 | AK76: 261.64448 | AL76: 238.34986 | AM76: 233.73571 | AN76: 264.86191 | AO76: 341.52284 | AP76: 162.93471 | AQ76: 175.52557 | AR76: 165 | AS76: 350 | AT76: 300 | AU76: 234 | AV76: 300
A77: 410425815 | B77: LINEA MOLHO BARBECUE 12X350G | C77: =IFERROR(VLOOKUP(Tabela1[[#This Row],[Código]],Cadastro!$A:$J,2,0),"Sem Cadastro") -> ALIMENTOS | D77: =IFERROR(VLOOKUP(Tabela1[[#This Row],[Código]],Cadastro!$A:$J,3,0),"Sem Cadastro") -> OUTROS | E77: =IFERROR(VLOOKUP(Tabela1[[#This Row],[Código]],Cadastro!$A:$J,4,0),"Sem Cadastro") -> MOLHOS | F77: =IFERROR(VLOOKUP(Tabela1[[#This Row],[Código]],Cadastro!$A:$J,5,0),"Sem Cadastro") -> BB | G77: MOLHOS LINEA | H77: 298 | I77: 251.67398 | J77: 284.44017 | K77: 382 | L77: 345.99526 | M77: 380 | N77: 369.83333 | O77: 412.92667 | P77: 450 | Q77: 413.49754 | R77: 390.61211 | S77: 330 | T77: 325 | U77: 350 | V77: 454.22 | W77: 450 | X77: 400 | Y77: 400 | Z77: 401 | AA77: 401 | AB77: 400 | AC77: 356 | AD77: 375 | AE77: 325 | AF77: 349 | AG77: 295.79664 | AH77: 320 | AI77: 320 | AJ77: 358.68855 | AK77: 374.13185 | AL77: 346.88456 | AM77: 313.08679 | AN77: 354.70667 | AO77: 376.46207 | AP77: 349.06334 | AQ77: 299.8889 | AR77: 287 | AS77: 320 | AT77: 342 | AU77: 0 | AV77: 0
A78: 410250103 | B78: LINEA GELATINA MORANGO 6X4X10G | C78: =IFERROR(VLOOKUP(Tabela1[[#This Row],[Código]],Cadastro!$A:$J,2,0),"Sem Cadastro") -> ALIMENTOS | D78: =IFERROR(VLOOKUP(Tabela1[[#This Row],[Código]],Cadastro!$A:$J,3,0),"Sem Cadastro") -> SOBREMESAS EM PÓ | E78: =IFERROR(VLOOKUP(Tabela1[[#This Row],[Código]],Cadastro!$A:$J,4,0),"Sem Cadastro") -> GELATINA | F78: =IFERROR(VLOOKUP(Tabela1[[#This Row],[Código]],Cadastro!$A:$J,5,0),"Sem Cadastro") -> CC | G78: GELATINA LINEA | H78: 161 | I78: 181.33333 | J78: 149.66678 | K78: 158 | L78: 248.71543 | M78: 225 | N78: 218.33333 | O78: 218.33333 | P78: 157 | Q78: 183.77669 | R78: 173.60538 | S78: 130 | T78: 150 | U78: 200 | V78: 223.52 | W78: 140 | X78: 250 | Y78: 200 | Z78: 197 | AA78: 197 | AB78: 150 | AC78: 147 | AD78: 200 | AE78: 200 | AF78: 215 | AG78: 138.92498 | AH78: 200 | AI78: 141.5796 | AJ78: 179.77082 | AK78: 226.18118 | AL78: 121.09334 | AM78: 123.41074 | AN78: 234.60634 | AO78: 171.12129 | AP78: 235.87672 | AQ78: 247.72084 | AR78: 199 | AS78: 250 | AT78: 242 | AU78: 157.3 | AV78: 200
A79: 410014749 | B79: ADOC STEVIA LIQ LINEA 6X2X60ML | C79: =IFERROR(VLOOKUP(Tabela1[[#This Row],[Código]],Cadastro!$A:$J,2,0),"Sem Cadastro") -> ADOÇANTES | D79: =IFERROR(VLOOKUP(Tabela1[[#This Row],[Código]],Cadastro!$A:$J,3,0),"Sem Cadastro") -> STEVIA | E79: =IFERROR(VLOOKUP(Tabela1[[#This Row],[Código]],Cadastro!$A:$J,4,0),"Sem Cadastro") -> STEVIA LÍQUIDO | F79: CC | G79: LIQUIDO STEVIA | H79: 183 | I79: 0 | J79: 0 | K79: 0 | L79: 0 | M79: 0 | N79: 0 | O79: 0 | P79: 0 | Q79: 0 | R79: 0 | S79: 0 | T79: 0 | U79: 0 | V79: 0 | W79: 0 | X79: 0 | Y79: 0 | Z79: 0 | AA79: 0 | AB79: 0 | AC79: 0 | AD79: 0 | AE79: 0 | AF79: 0 | AG79: 0 | AH79: 0 | AI79: 0 | AJ79: 0 | AK79: 0 | AL79: 0 | AM79: 0 | AN79: 0 | AO79: 0 | AP79: 0 | AQ79: 0 | AR79: 0 | AS79: 0 | AT79: 0 | AU79: 0 | AV79: 0
A80: 410040857 | B80: LINEA GELEIA DE MACA COM CANELA 12X230G | C80: =IFERROR(VLOOKUP(Tabela1[[#This Row],[Código]],Cadastro!$A:$J,2,0),"Sem Cadastro") -> ALIMENTOS | D80: =IFERROR(VLOOKUP(Tabela1[[#This Row],[Código]],Cadastro!$A:$J,3,0),"Sem Cadastro") -> GELEIAS | E80: =IFERROR(VLOOKUP(Tabela1[[#This Row],[Código]],Cadastro!$A:$J,4,0),"Sem Cadastro") -> GELEIA DE FRUTAS | F80: =IFERROR(VLOOKUP(Tabela1[[#This Row],[Código]],Cadastro!$A:$J,5,0),"Sem Cadastro") -> CC | G80: GELEIA LINEA | H80: 0 | I80: 0 | J80: 0 | K80: 0 | L80: 0 | M80: 0 | N80: 0 | O80: 0 | P80: 0 | Q80: 0 | R80: 0 | S80: 0 | T80: 0 | U80: 0 | V80: 0 | W80: 0 | X80: 0 | Y80: 0 | Z80: 0 | AA80: 0 | AB80: 0 | AC80: 0 | AD80: 0 | AE80: 0 | AF80: 0 | AG80: 0 | AH80: 0 | AI80: 1300 | AJ80: 1357.092 | AK80: 1480.5086 | AL80: 1520.1002 | AM80: 1349.2231 | AN80: 612.04348 | AO80: 727.06236 | AP80: 292.62221 | AQ80: 266.03257 | AR80: 182 | AS80: 230 | AT80: 325 | AU80: 290 | AV80: 310
A81: 410312064 | B81: LINEA CHOC VEGANO BR C/ FR VERM 4X15X30G | C81: =IFERROR(VLOOKUP(Tabela1[[#This Row],[Código]],Cadastro!$A:$J,2,0),"Sem Cadastro") -> ALIMENTOS | D81: =IFERROR(VLOOKUP(Tabela1[[#This Row],[Código]],Cadastro!$A:$J,3,0),"Sem Cadastro") -> CHOCOLATES | E81: =IFERROR(VLOOKUP(Tabela1[[#This Row],[Código]],Cadastro!$A:$J,4,0),"Sem Cadastro") -> VEGANO | F81: =IFERROR(VLOOKUP(Tabela1[[#This Row],[Código]],Cadastro!$A:$J,5,0),"Sem Cadastro") -> BC | G81: CHOCOLATE LINEA | H81: 294 | I81: 119 | J81: 389 | K81: 389 | L81: 390.12219 | M81: 499 | N81: 659.5 | O81: 650 | P81: 800 | Q81: 551.33006 | R81: 520.81615 | S81: 496 | T81: 500 | U81: 500 | V81: 500 | W81: 450 | X81: 400 | Y81: 350 | Z81: 365 | AA81: 365 | AB81: 375 | AC81: 422 | AD81: 370 | AE81: 350 | AF81: 375 | AG81: 225.6263 | AH81: 367.5 | AI81: 350 | AJ81: 332.31025 | AK81: 329.25506 | AL81: 317.0594 | AM81: 350.80965 | AN81: 356.57573 | AO81: 148.57204 | AP81: 171.27451 | AQ81: 109.92094 | AR81: 101 | AS81: 300 | AT81: 150 | AU81: 180 | AV81: 205
A82: 410025606 | B82: LINEA ADOC SUCRAL PO 24X100X0,5G | C82: =IFERROR(VLOOKUP(Tabela1[[#This Row],[Código]],Cadastro!$A:$J,2,0),"Sem Cadastro") -> ADOÇANTES | D82: =IFERROR(VLOOKUP(Tabela1[[#This Row],[Código]],Cadastro!$A:$J,3,0),"Sem Cadastro") -> SUCRALOSE | E82: =IFERROR(VLOOKUP(Tabela1[[#This Row],[Código]],Cadastro!$A:$J,4,0),"Sem Cadastro") -> SUCRALOSE PÓ | F82: =IFERROR(VLOOKUP(Tabela1[[#This Row],[Código]],Cadastro!$A:$J,5,0),"Sem Cadastro") -> BB | G82: PO LINEA | H82: 0 | I82: 0 | J82: 0 | K82: 165 | L82: 168.48465 | M82: 224 | N82: 300 | O82: 200 | P82: 0 | Q82: 0 | R82: 0 | S82: 0 | T82: 0 | U82: 0 | V82: 200 | W82: 200 | X82: 200 | Y82: 190 | Z82: 228 | AA82: 228 | AB82: 275 | AC82: 273 | AD82: 200 | AE82: 180 | AF82: 118 | AG82: 142.39743 | AH82: 100 | AI82: 100 | AJ82: 119.1157 | AK82: 186.59911 | AL82: 214.90709 | AM82: 253.55588 | AN82: 274.04426 | AO82: 224.36841 | AP82: 217.32892 | AQ82: 228.42884 | AR82: 164 | AS82: 180 | AT82: 204 | AU82: 120 | AV82: 135
A83: 410026208 | B83: LINEA ADOC XILITOL PO 6X40X5G | C83: =IFERROR(VLOOKUP(Tabela1[[#This Row],[Código]],Cadastro!$A:$J,2,0),"Sem Cadastro") -> ADOÇANTES | D83: =IFERROR(VLOOKUP(Tabela1[[#This Row],[Código]],Cadastro!$A:$J,3,0),"Sem Cadastro") -> XILITOL | E83: =IFERROR(VLOOKUP(Tabela1[[#This Row],[Código]],Cadastro!$A:$J,4,0),"Sem Cadastro") -> XILITOL PÓ | F83: =IFERROR(VLOOKUP(Tabela1[[#This Row],[Código]],Cadastro!$A:$J,5,0),"Sem Cadastro") -> CC | G83: XILITOL LINEA | H83: 458 | I83: 424.74992 | J83: 395.09121 | K83: 449 | L83: 622.79147 | M83: 500 | N83: 450 | O83: 600 | P83: 480 | Q83: 0 | R83: 0 | S83: 0 | T83: 800 | U83: 500 | V83: 500 | W83: 600 | X83: 613.31982 | Y83: 600 | Z83: 543 | AA83: 543 | AB83: 700 | AC83: 784 | AD83: 550 | AE83: 550 | AF83: 483 | AG83: 363.20005 | AH83: 388.87477 | AI83: 250 | AJ83: 330.98521 | AK83: 260.88076 | AL83: 285.64617 | AM83: 245.32571 | AN83: 242.48205 | AO83: 159.23048 | AP83: 176.11685 | AQ83: 158.16469 | AR83: 129 | AS83: 144 | AT83: 170 | AU83: 170 | AV83: 170
A84: 410040557 | B84: LINEA GELEIA DE CEBOLA CARAMELIZADA 12X230G | C84: =IFERROR(VLOOKUP(Tabela1[[#This Row],[Código]],Cadastro!$A:$J,2,0),"Sem Cadastro") -> ALIMENTOS | D84: =IFERROR(VLOOKUP(Tabela1[[#This Row],[Código]],Cadastro!$A:$J,3,0),"Sem Cadastro") -> GELEIAS | E84: =IFERROR(VLOOKUP(Tabela1[[#This Row],[Código]],Cadastro!$A:$J,4,0),"Sem Cadastro") -> GELEIAS ESPECIAIS | F84: =IFERROR(VLOOKUP(Tabela1[[#This Row],[Código]],Cadastro!$A:$J,5,0),"Sem Cadastro") -> CC | G84: GELEIA LINEA | H84: 318.76737 | I84: 423.16718 | J84: 290.66829 | K84: 383 | L84: 449.29239 | M84: 500 | N84: 280 | O84: 400 | P84: 377.80889 | Q84: 215 | R84: 450 | S84: 437 | T84: 400 | U84: 400 | V84: 400 | W84: 400 | X84: 400 | Y84: 400 | Z84: 353 | AA84: 353 | AB84: 300 | AC84: 343 | AD84: 300 | AE84: 300 | AF84: 322 | AG84: 269.88106 | AH84: 262.53396 | AI84: 259.2928 | AJ84: 251.69257 | AK84: 337.34638 | AL84: 339.336 | AM84: 342.84288 | AN84: 330.48119 | AO84: 234.8586 | AP84: 177.5298 | AQ84: 175.12121 | AR84: 139 | AS84: 154 | AT84: 180 | AU84: 170 | AV84: 175
A85: 410060299 | B85: LINEA SHAKE PREMIUM CHOC 12X210G | C85: =IFERROR(VLOOKUP(Tabela1[[#This Row],[Código]],Cadastro!$A:$J,2,0),"Sem Cadastro") -> ALIMENTOS | D85: =IFERROR(VLOOKUP(Tabela1[[#This Row],[Código]],Cadastro!$A:$J,3,0),"Sem Cadastro") -> SHAKE | E85: =IFERROR(VLOOKUP(Tabela1[[#This Row],[Código]],Cadastro!$A:$J,4,0),"Sem Cadastro") -> SHAKE | F85: =IFERROR(VLOOKUP(Tabela1[[#This Row],[Código]],Cadastro!$A:$J,5,0),"Sem Cadastro") -> LANÇAMENTO | G85: SHAKE LINEA | H85: 0 | I85: 0 | J85: 0 | K85: 0 | L85: 0 | M85: 0 | N85: 0 | O85: 0 | P85: 0 | Q85: 0 | R85: 0 | S85: 0 | T85: 0 | U85: 0 | V85: 0 | W85: 0 | X85: 0 | Y85: 0 | Z85: 0 | AA85: 0 | AB85: 0 | AC85: 0 | AD85: 0 | AE85: 0 | AF85: 0 | AG85: 0 | AH85: 0 | AI85: 0 | AJ85: 0 | AK85: 0 | AL85: 0 | AM85: 0 | AN85: 0 | AO85: 0 | AP85: 239 | AQ85: 239.06361 | AR85: 325 | AS85: 479 | AT85: 292 | AU85: 391 | AV85: 397
A86: 410060399 | B86: LINEA SHAKE PREMIUM BAUNILHA 12X210G | C86: =IFERROR(VLOOKUP(Tabela1[[#This Row],[Código]],Cadastro!$A:$J,2,0),"Sem Cadastro") -> ALIMENTOS | D86: =IFERROR(VLOOKUP(Tabela1[[#This Row],[Código]],Cadastro!$A:$J,3,0),"Sem Cadastro") -> SHAKE | E86: =IFERROR(VLOOKUP(Tabela1[[#This Row],[Código]],Cadastro!$A:$J,4,0),"Sem Cadastro") -> SHAKE | F86: =IFERROR(VLOOKUP(Tabela1[[#This Row],[Código]],Cadastro!$A:$J,5,0),"Sem Cadastro") -> LANÇAMENTO | G86: SHAKE LINEA | H86: 0 | I86: 0 | J86: 0 | K86: 0 | L86: 0 | M86: 0 | N86: 0 | O86: 0 | P86: 0 | Q86: 0 | R86: 0 | S86: 0 | T86: 0 | U86: 0 | V86: 0 | W86: 0 | X86: 0 | Y86: 0 | Z86: 0 | AA86: 0 | AB86: 0 | AC86: 0 | AD86: 0 | AE86: 0 | AF86: 0 | AG86: 0 | AH86: 0 | AI86: 0 | AJ86: 0 | AK86: 0 | AL86: 0 | AM86: 0 | AN86: 0 | AO86: 0 | AP86: 429 | AQ86: 156.99611 | AR86: 316 | AS86: 472 | AT86: 281 | AU86: 382 | AV86: 387
A87: 410030604 | B87: LINEA BARRA CEREAIS TRUFA CHOCOLATE 12X3X20G | C87: =IFERROR(VLOOKUP(Tabela1[[#This Row],[Código]],Cadastro!$A:$J,2,0),"Sem Cadastro") -> ALIMENTOS | D87: =IFERROR(VLOOKUP(Tabela1[[#This Row],[Código]],Cadastro!$A:$J,3,0),"Sem Cadastro") -> BARRAS | E87: =IFERROR(VLOOKUP(Tabela1[[#This Row],[Código]],Cadastro!$A:$J,4,0),"Sem Cadastro") -> BARRA CEREAIS | F87: =IFERROR(VLOOKUP(Tabela1[[#This Row],[Código]],Cadastro!$A:$J,5,0),"Sem Cadastro") -> CC | G87: BARRA LINEA | H87: 504 | I87: 352.96872 | J87: 390.37475 | K87: 397 | L87: 151.35538 | M87: 215 | N87: 0 | O87: 0 | P87: 800 | Q87: 459.44171 | R87: 434.01346 | S87: 357 | T87: 325 | U87: 400 | V87: 500 | W87: 450 | X87: 375 | Y87: 350 | Z87: 329 | AA87: 329 | AB87: 280 | AC87: 245 | AD87: 225 | AE87: 225 | AF87: 242 | AG87: 208.64422 | AH87: 223.06652 | AI87: 211 | AJ87: 242.82432 | AK87: 223.24697 | AL87: 288.43275 | AM87: 239.22761 | AN87: 265.96133 | AO87: 213.72238 | AP87: 199.91123 | AQ87: 152.10681 | AR87: 157 | AS87: 140 | AT87: 160 | AU87: 0 | AV87: 0
A88: 410342157 | B88: LINEA DOCE DE LEITE COCO 12X210G | C88: =IFERROR(VLOOKUP(Tabela1[[#This Row],[Código]],Cadastro!$A:$J,2,0),"Sem Cadastro") -> ALIMENTOS | D88: =IFERROR(VLOOKUP(Tabela1[[#This Row],[Código]],Cadastro!$A:$J,3,0),"Sem Cadastro") -> OUTROS | E88: =IFERROR(VLOOKUP(Tabela1[[#This Row],[Código]],Cadastro!$A:$J,4,0),"Sem Cadastro") -> DOCE DE LEITE | F88: =IFERROR(VLOOKUP(Tabela1[[#This Row],[Código]],Cadastro!$A:$J,5,0),"Sem Cadastro") -> BC | G88: DOCE DE LEITE LINEA | H88: 320 | I88: 209.92752 | J88: 226.47214 | K88: 211 | L88: 507.45971 | M88: 209 | N88: 168.58333 | O88: 234.91667 | P88: 244.88333 | Q88: 211.34319 | R88: 199.64619 | S88: 176 | T88: 200 | U88: 250 | V88: 306.57 | W88: 275 | X88: 275 | Y88: 225 | Z88: 200 | AA88: 200 | AB88: 200 | AC88: 150 | AD88: 150 | AE88: 150 | AF88: 193 | AG88: 122.6268 | AH88: 200 | AI88: 280 | AJ88: 268.85603 | AK88: 271.3162 | AL88: 324.57131 | AM88: 267.53222 | AN88: 292.14763 | AO88: 254.79204 | AP88: 232.34876 | AQ88: 200.75094 | AR88: 229 | AS88: 257 | AT88: 277 | AU88: 389 | AV88: 0
A89: 410251203 | B89: LINEA GELATINA UVA 6X4X10G | C89: =IFERROR(VLOOKUP(Tabela1[[#This Row],[Código]],Cadastro!$A:$J,2,0),"Sem Cadastro") -> ALIMENTOS | D89: =IFERROR(VLOOKUP(Tabela1[[#This Row],[Código]],Cadastro!$A:$J,3,0),"Sem Cadastro") -> SOBREMESAS EM PÓ | E89: =IFERROR(VLOOKUP(Tabela1[[#This Row],[Código]],Cadastro!$A:$J,4,0),"Sem Cadastro") -> GELATINA | F89: =IFERROR(VLOOKUP(Tabela1[[#This Row],[Código]],Cadastro!$A:$J,5,0),"Sem Cadastro") -> CC | G89: GELATINA LINEA | H89: 120 | I89: 128 | J89: 138.8344 | K89: 139 | L89: 88.253863 | M89: 176 | N89: 120.5 | O89: 126.66667 | P89: 125 | Q89: 114.86043 | R89: 108.50336 | S89: 91 | T89: 100 | U89: 100 | V89: 148.91 | W89: 100 | X89: 165 | Y89: 120 | Z89: 143 | AA89: 143 | AB89: 100 | AC89: 98 | AD89: 90 | AE89: 90 | AF89: 108 | AG89: 95.116488 | AH89: 200 | AI89: 190 | AJ89: 226.66984 | AK89: 185.82184 | AL89: 109.62828 | AM89: 109.28079 | AN89: 193.68511 | AO89: 157.49019 | AP89: 77.285089 | AQ89: 80.309045 | AR89: 207 | AS89: 250 | AT89: 251 | AU89: 164.45 | AV89: 200
A90: 410030004 | B90: LINEA BARRA CEREAIS BANANA C/ AVEIA 12X3X20G | C90: =IFERROR(VLOOKUP(Tabela1[[#This Row],[Código]],Cadastro!$A:$J,2,0),"Sem Cadastro") -> ALIMENTOS | D90: =IFERROR(VLOOKUP(Tabela1[[#This Row],[Código]],Cadastro!$A:$J,3,0),"Sem Cadastro") -> BARRAS | E90: =IFERROR(VLOOKUP(Tabela1[[#This Row],[Código]],Cadastro!$A:$J,4,0),"Sem Cadastro") -> BARRA CEREAIS | F90: =IFERROR(VLOOKUP(Tabela1[[#This Row],[Código]],Cadastro!$A:$J,5,0),"Sem Cadastro") -> CC | G90: BARRA LINEA | H90: 458 | I90: 447.02859 | J90: 481.14457 | K90: 444 | L90: 100.28848 | M90: 0 | N90: 0 | O90: 0 | P90: 1000 | Q90: 643.2184 | R90: 607.61884 | S90: 399 | T90: 350 | U90: 400 | V90: 500 | W90: 500 | X90: 400 | Y90: 300 | Z90: 273 | AA90: 273 | AB90: 240 | AC90: 237 | AD90: 218 | AE90: 200 | AF90: 268 | AG90: 188.6826 | AH90: 194.6916 | AI90: 192 | AJ90: 227.55762 | AK90: 136.91141 | AL90: 263.36416 | AM90: 225.29806 | AN90: 258.34807 | AO90: 206.51073 | AP90: 185.75092 | AQ90: 132.57198 | AR90: 139 | AS90: 156 | AT90: 164 | AU90: 0 | AV90: 0
A91: 410313499 | B91: LINEA CHOCOLATE LEITE 8X15X13G | C91: =IFERROR(VLOOKUP(Tabela1[[#This Row],[Código]],Cadastro!$A:$J,2,0),"Sem Cadastro") -> ALIMENTOS | D91: =IFERROR(VLOOKUP(Tabela1[[#This Row],[Código]],Cadastro!$A:$J,3,0),"Sem Cadastro") -> CHOCOLATES | E91: =IFERROR(VLOOKUP(Tabela1[[#This Row],[Código]],Cadastro!$A:$J,4,0),"Sem Cadastro") -> IMPULSO | F91: =IFERROR(VLOOKUP(Tabela1[[#This Row],[Código]],Cadastro!$A:$J,5,0),"Sem Cadastro") -> BC | G91: CHOCOLATE LINEA | H91: 413 | I91: 488.88668 | J91: 373.91624 | K91: 447 | L91: 349.00391 | M91: 381 | N91: 750 | O91: 446.8 | P91: 500 | Q91: 459.44171 | R91: 434.01346 | S91: 391 | T91: 400 | U91: 400 | V91: 400 | W91: 400 | X91: 350 | Y91: 375 | Z91: 407 | AA91: 407 | AB91: 350 | AC91: 392 | AD91: 350 | AE91: 300 | AF91: 322 | AG91: 300.15268 | AH91: 309.03443 | AI91: 280 | AJ91: 249.70409 | AK91: 273.09237 | AL91: 268.10643 | AM91: 273.68932 | AN91: 290.91936 | AO91: 188.21219 | AP91: 215.98921 | AQ91: 183.68611 | AR91: 199 | AS91: 250 | AT91: 250 | AU91: 168 | AV91: 197
... A108: 410312164 | B108: LINEA CHOC VEGANO LEITE C/ NIBS 4X15X30G | C108: =IFERROR(VLOOKUP(Tabela1[[#This Row],[Código]],Cadastro!$A:$J,2,0),"Sem Cadastro") -> ALIMENTOS | D108: =IFERROR(VLOOKUP(Tabela1[[#This Row],[Código]],Cadastro!$A:$J,3,0),"Sem Cadastro") -> CHOCOLATES | E108: =IFERROR(VLOOKUP(Tabela1[[#This Row],[Código]],Cadastro!$A:$J,4,0),"Sem Cadastro") -> VEGANO | F108: =IFERROR(VLOOKUP(Tabela1[[#This Row],[Código]],Cadastro!$A:$J,5,0),"Sem Cadastro") -> BC | G108: CHOCOLATE LINEA | H108: 441 | I108: 191 | J108: 389 | K108: 389 | L108: 390.12219 | M108: 429 | N108: 350.16667 | O108: 400 | P108: 500 | Q108: 357.44565 | R108: 337.66247 | S108: 312 | T108: 300 | U108: 300 | V108: 259 | W108: 320 | X108: 300 | Y108: 250 | Z108: 230 | AA108: 230 | AB108: 325 | AC108: 245 | AD108: 300 | AE108: 220 | AF108: 322 | AG108: 154.34665 | AH108: 367.5 | AI108: 260 | AJ108: 263.43387 | AK108: 268.40932 | AL108: 243.91288 | AM108: 238.98541 | AN108: 304.76915 | AO108: 150.34866 | AP108: 71.273543 | AQ108: 73.096419 | AR108: 81 | AS108: 100 | AT108: 100 | AU108: 100 | AV108: 145
A109: 410040647 | B109: LINEA GELEIA DE UVA 6X2X230G | C109: =IFERROR(VLOOKUP(Tabela1[[#This Row],[Código]],Cadastro!$A:$J,2,0),"Sem Cadastro") -> ALIMENTOS | D109: =IFERROR(VLOOKUP(Tabela1[[#This Row],[Código]],Cadastro!$A:$J,3,0),"Sem Cadastro") -> GELEIAS | E109: =IFERROR(VLOOKUP(Tabela1[[#This Row],[Código]],Cadastro!$A:$J,4,0),"Sem Cadastro") -> GELEIA DE FRUTAS | F109: CC | G109: GELEIA LINEA | H109: 0 | I109: 0 | J109: 0 | K109: 46 | L109: 70.201937 | M109: 75 | N109: 60 | O109: 60 | P109: 50 | Q109: 50 | R109: 50 | S109: 45 | T109: 50 | U109: 50 | V109: 53.71 | W109: 50 | X109: 70 | Y109: 50 | Z109: 48 | AA109: 48 | AB109: 0 | AC109: 0 | AD109: 0 | AE109: 0 | AF109: 0 | AG109: 0 | AH109: 0 | AI109: 0 | AJ109: 0 | AK109: 0 | AL109: 0 | AM109: 0 | AN109: 0 | AO109: 0 | AP109: 0 | AQ109: 0 | AR109: 0 | AS109: 0 | AT109: 0 | AU109: 0 | AV109: 0
A110: 410040247 | B110: LINEA GELEIA DE PIMENTA VERMELHA 6X2X230G | C110: =IFERROR(VLOOKUP(Tabela1[[#This Row],[Código]],Cadastro!$A:$J,2,0),"Sem Cadastro") -> ALIMENTOS | D110: =IFERROR(VLOOKUP(Tabela1[[#This Row],[Código]],Cadastro!$A:$J,3,0),"Sem Cadastro") -> GELEIAS | E110: =IFERROR(VLOOKUP(Tabela1[[#This Row],[Código]],Cadastro!$A:$J,4,0),"Sem Cadastro") -> GELEIAS ESPECIAIS | F110: =IFERROR(VLOOKUP(Tabela1[[#This Row],[Código]],Cadastro!$A:$J,5,0),"Sem Cadastro") -> CC | G110: GELEIA LINEA | H110: 42 | I110: 57.666667 | J110: 62.900734 | K110: 42 | L110: 49.141356 | M110: 61 | N110: 125 | O110: 137.33333 | P110: 50 | Q110: 50 | R110: 50 | S110: 41 | T110: 45 | U110: 45 | V110: 61.06 | W110: 60 | X110: 75 | Y110: 75 | Z110: 96 | AA110: 96 | AB110: 50 | AC110: 49 | AD110: 40 | AE110: 40 | AF110: 54 | AG110: 53.569577 | AH110: 55.275615 | AI110: 70 | AJ110: 72 | AK110: 61.092139 | AL110: 66.520134 | AM110: 34.309165 | AN110: 65.222426 | AO110: 41.274808 | AP110: 38.072699 | AQ110: 31.508099 | AR110: 46 | AS110: 40 | AT110: 50 | AU110: 50 | AV110: 55
A111: 410066399 | B111: LINEA SHAKE IOGURT C FR VERM 12X210G | C111: =IFERROR(VLOOKUP(Tabela1[[#This Row],[Código]],Cadastro!$A:$J,2,0),"Sem Cadastro") -> ALIMENTOS | D111: =IFERROR(VLOOKUP(Tabela1[[#This Row],[Código]],Cadastro!$A:$J,3,0),"Sem Cadastro") -> SHAKE | E111: =IFERROR(VLOOKUP(Tabela1[[#This Row],[Código]],Cadastro!$A:$J,4,0),"Sem Cadastro") -> SHAKE | F111: =IFERROR(VLOOKUP(Tabela1[[#This Row],[Código]],Cadastro!$A:$J,5,0),"Sem Cadastro") -> LANÇAMENTO | G111: SHAKE LINEA | H111: 0 | I111: 0 | J111: 0 | K111: 0 | L111: 0 | M111: 0 | N111: 0 | O111: 0 | P111: 0 | Q111: 0 | R111: 0 | S111: 0 | T111: 0 | U111: 0 | V111: 0 | W111: 0 | X111: 0 | Y111: 0 | Z111: 0 | AA111: 0 | AB111: 0 | AC111: 0 | AD111: 0 | AE111: 0 | AF111: 0 | AG111: 0 | AH111: 0 | AI111: 0 | AJ111: 0 | AK111: 0 | AL111: 0 | AM111: 0 | AN111: 0 | AO111: 0 | AP111: 0 | AQ111: 0 | AR111: 48 | AS111: 59 | AT111: 52 | AU111: 58 | AV111: 61
A112: 410060499 | B112: LINEA SHAKE COOKIES'N CREAM 12X210G | C112: =IFERROR(VLOOKUP(Tabela1[[#This Row],[Código]],Cadastro!$A:$J,2,0),"Sem Cadastro") -> ALIMENTOS | D112: =IFERROR(VLOOKUP(Tabela1[[#This Row],[Código]],Cadastro!$A:$J,3,0),"Sem Cadastro") -> SHAKE | E112: =IFERROR(VLOOKUP(Tabela1[[#This Row],[Código]],Cadastro!$A:$J,4,0),"Sem Cadastro") -> SHAKE | F112: =IFERROR(VLOOKUP(Tabela1[[#This Row],[Código]],Cadastro!$A:$J,5,0),"Sem Cadastro") -> LANÇAMENTO | G112: SHAKE LINEA | H112: 0 | I112: 0 | J112: 0 | K112: 0 | L112: 0 | M112: 0 | N112: 0 | O112: 0 | P112: 0 | Q112: 0 | R112: 0 | S112: 0 | T112: 0 | U112: 0 | V112: 0 | W112: 0 | X112: 0 | Y112: 0 | Z112: 0 | AA112: 0 | AB112: 0 | AC112: 0 | AD112: 0 | AE112: 0 | AF112: 0 | AG112: 0 | AH112: 0 | AI112: 0 | AJ112: 0 | AK112: 0 | AL112: 0 | AM112: 0 | AN112: 0 | AO112: 0 | AP112: 0 | AQ112: 0 | AR112: 138 | AS112: 188 | AT112: 134 | AU112: 167 | AV112: 170
A113: 410030302 | B113: LINEA BARRA CEREAIS NUTS C/ CHOCO 12X12X20G | C113: =IFERROR(VLOOKUP(Tabela1[[#This Row],[Código]],Cadastro!$A:$J,2,0),"Sem Cadastro") -> ALIMENTOS | D113: =IFERROR(VLOOKUP(Tabela1[[#This Row],[Código]],Cadastro!$A:$J,3,0),"Sem Cadastro") -> BARRAS | E113: =IFERROR(VLOOKUP(Tabela1[[#This Row],[Código]],Cadastro!$A:$J,4,0),"Sem Cadastro") -> BARRA CEREAIS | F113: =IFERROR(VLOOKUP(Tabela1[[#This Row],[Código]],Cadastro!$A:$J,5,0),"Sem Cadastro") -> DESCONTINUADO | G113: BARRA LINEA | H113: 252 | I113: 216.87652 | J113: 191.10602 | K113: 242 | L113: 212.29066 | M113: 0 | N113: 0 | O113: 0 | P113: 308.06111 | Q113: 285.11421 | R113: 217.00673 | S113: 172 | T113: 200 | U113: 200 | V113: 258.27 | W113: 250 | X113: 147.19595 | Y113: 140 | Z113: 146 | AA113: 146 | AB113: 140 | AC113: 118 | AD113: 110 | AE113: 116 | AF113: 134 | AG113: 92.60491 | AH113: 95.39806 | AI113: 89 | AJ113: 112.96386 | AK113: 87.55248 | AL113: 144.74373 | AM113: 134.16185 | AN113: 186.38194 | AO113: 89.17558 | AP113: 0 | AQ113: 0 | AR113: 0 | AS113: 0 | AT113: 0 | AU113: 0 | AV113: 0
A114: 410030304 | B114: LINEA BARRA CEREAIS NUTS C/ CHOCO 12X3X20G | C114: =IFERROR(VLOOKUP(Tabela1[[#This Row],[Código]],Cadastro!$A:$J,2,0),"Sem Cadastro") -> ALIMENTOS | D114: =IFERROR(VLOOKUP(Tabela1[[#This Row],[Código]],Cadastro!$A:$J,3,0),"Sem Cadastro") -> BARRAS | E114: =IFERROR(VLOOKUP(Tabela1[[#This Row],[Código]],Cadastro!$A:$J,4,0),"Sem Cadastro") -> BARRA CEREAIS | F114: =IFERROR(VLOOKUP(Tabela1[[#This Row],[Código]],Cadastro!$A:$J,5,0),"Sem Cadastro") -> DESCONTINUADO | G114: BARRA LINEA | H114: 320 | I114: 333.56018 | J114: 376.84976 | K114: 329 | L114: 255.53505 | M114: 63 | N114: 0 | O114: 0 | P114: 618.59722 | Q114: 459.44171 | R114: 434.01346 | S114: 347 | T114: 300 | U114: 450 | V114: 450 | W114: 400 | X114: 400 | Y114: 325 | Z114: 179 | AA114: 179 | AB114: 150 | AC114: 157 | AD114: 150 | AE114: 150 | AF114: 161 | AG114: 127.78643 | AH114: 123.76638 | AI114: 122 | AJ114: 156.15147 | AK114: 76.785493 | AL114: 183.88295 | AM114: 1.4566584 | AN114: 12.710304 | AO114: 0 | AP114: 0 | AQ114: 0 | AR114: 0 | AS114: 0 | AT114: 0 | AU114: 0 | AV114: 0
A115: 410031105 | B115: LINEA BARRA PROTEINA CHEESECAKE MORANGO 6X12X32G | C115: =IFERROR(VLOOKUP(Tabela1[[#This Row],[Código]],Cadastro!$A:$J,2,0),"Sem Cadastro") -> ALIMENTOS | D115: =IFERROR(VLOOKUP(Tabela1[[#This Row],[Código]],Cadastro!$A:$J,3,0),"Sem Cadastro") -> BARRAS | E115: =IFERROR(VLOOKUP(Tabela1[[#This Row],[Código]],Cadastro!$A:$J,4,0),"Sem Cadastro") -> BARRA PROTEÍNA | F115: =IFERROR(VLOOKUP(Tabela1[[#This Row],[Código]],Cadastro!$A:$J,5,0),"Sem Cadastro") -> DESCONTINUADO | G115: BARRA PROTEINA LINEA | H115: 245 | I115: 239 | J115: 79.905742 | K115: 111 | L115: 204.42804 | M115: 0 | N115: 0 | O115: 0 | P115: 0 | Q115: 0 | R115: 0 | S115: 0 | T115: 0 | U115: 0 | V115: 0 | W115: 0 | X115: 0 | Y115: 0 | Z115: 0 | AA115: 0 | AB115: 0 | AC115: 0 | AD115: 0 | AE115: 0 | AF115: 0 | AG115: 0 | AH115: 0 | AI115: 0 | AJ115: 0 | AK115: 0 | AL115: 0 | AM115: 0 | AN115: 0 | AO115: 0 | AP115: 0 | AQ115: 0 | AR115: 0 | AS115: 0 | AT115: 0 | AU115: 0 | AV115: 0
A116: 410030805 | B116: LINEA BARRA PROTEINA CHOCOLATE 6X12X32G | C116: =IFERROR(VLOOKUP(Tabela1[[#This Row],[Código]],Cadastro!$A:$J,2,0),"Sem Cadastro") -> ALIMENTOS | D116: =IFERROR(VLOOKUP(Tabela1[[#This Row],[Código]],Cadastro!$A:$J,3,0),"Sem Cadastro") -> BARRAS | E116: =IFERROR(VLOOKUP(Tabela1[[#This Row],[Código]],Cadastro!$A:$J,4,0),"Sem Cadastro") -> BARRA PROTEÍNA | F116: =IFERROR(VLOOKUP(Tabela1[[#This Row],[Código]],Cadastro!$A:$J,5,0),"Sem Cadastro") -> DESCONTINUADO | G116: BARRA PROTEINA LINEA | H116: 238 | I116: 293.21667 | J116: 185.8186 | K116: 237 | L116: 7.0201937 | M116: 0 | N116: 0 | O116: 0 | P116: 0 | Q116: 0 | R116: 0 | S116: 0 | T116: 0 | U116: 0 | V116: 0 | W116: 0 | X116: 0 | Y116: 0 | Z116: 0 | AA116: 0 | AB116: 0 | AC116: 0 | AD116: 0 | AE116: 0 | AF116: 0 | AG116: 0 | AH116: 0 | AI116: 0 | AJ116: 0 | AK116: 0 | AL116: 0 | AM116: 0 | AN116: 0 | AO116: 0 | AP116: 0 | AQ116: 0 | AR116: 0 | AS116: 0 | AT116: 0 | AU116: 0 | AV116: 0
...

Sheet Conversão
A1: Código | B1: Descrição do Produto | C1: jan/26 | D1: fev/26 | E1: mar/26 | F1: abr/26 | G1: mai/26 | H1: jun/26 | I1: jul/26 | J1: ago/26 | K1: set/26 | L1: out/26 | M1: nov/26 | N1: dez/26 | O1: DE/PARA | P1: und/caixa | Q1: M2 | R1: M3 | S1: M4
A2: 430010020 | B2: ADOCANTE SUCRALOSE LIQUIDO LINEA 25ML | C2: 109 | D2: 109 | E2: 125 | F2: 135 | G2: 135 | H2: 143 | I2: 146 | J2: 146 | K2: 151 | L2: 151 | M2: 219 | N2: 113 | O2: 410010020 | P2: =IFERROR(VLOOKUP(A2,'[1]Padronização 43'!$B:$Q,16,0),0) -> 24 | Q2: =IFERROR(I2/P2,0) -> 6.0833333 | R2: =IFERROR(J2/$P$2,0) -> 6.0833333 | S2: =IFERROR(K2/$P$2,0) -> 6.2916667
A3: 430010021 | B3: ADOCANTE SUCRALOSE LIQUIDO LINEA 75ML | C3: 600 | D3: 600 | E3: 683 | F3: 739 | G3: 739 | H3: 785 | I3: 803 | J3: 803 | K3: 831 | L3: 831 | M3: 1201 | N3: 619 | O3: 410010021 | P3: =IFERROR(VLOOKUP(A3,'[1]Padronização 43'!$B:$Q,16,0),0) -> 24 | Q3: =IFERROR(I3/P3,0) -> 33.458333 | R3: =IFERROR(J3/$P$2,0) -> 33.458333 | S3: =IFERROR(K3/$P$2,0) -> 34.625
A4: 430014791 | B4: ADOCANTE STEVIA LIQUIDO LINEA 25ML | C4: 85 | D4: 85 | E4: 97 | F4: 105 | G4: 105 | H4: 112 | I4: 114 | J4: 114 | K4: 118 | L4: 118 | M4: 171 | N4: 88 | O4: 410014791 | P4: =IFERROR(VLOOKUP(A4,'[1]Padronização 43'!$B:$Q,16,0),0) -> 12 | Q4: =IFERROR(I4/P4,0) -> 9.5 | R4: =IFERROR(J4/$P$2,0) -> 4.75 | S4: =IFERROR(K4/$P$2,0) -> 4.9166667
A5: 430014792 | B5: ADOCANTE STEVIA LIQUIDO LINEA 60ML | C5: 469 | D5: 469 | E5: 534 | F5: 577 | G5: 577 | H5: 613 | I5: 627 | J5: 627 | K5: 649 | L5: 649 | M5: 938 | N5: 483 | O5: 410014792 | P5: =IFERROR(VLOOKUP(A5,'[1]Padronização 43'!$B:$Q,16,0),0) -> 12 | Q5: =IFERROR(I5/P5,0) -> 52.25 | R5: =IFERROR(J5/$P$2,0) -> 26.125 | S5: =IFERROR(K5/$P$2,0) -> 27.041667
A6: 430014793 | B6: ADOCANTE STEVIA EM PO LINEA 50 SACHES | C6: 28 | D6: 28 | E6: 32 | F6: 35 | G6: 35 | H6: 37 | I6: 38 | J6: 38 | K6: 39 | L6: 39 | M6: 56 | N6: 29 | O6: 410026410 | P6: =IFERROR(VLOOKUP(A6,'[1]Padronização 43'!$B:$Q,16,0),0) -> 12 | Q6: =IFERROR(I6/P6,0) -> 3.1666667 | R6: =IFERROR(J6/$P$2,0) -> 1.5833333 | S6: =IFERROR(K6/$P$2,0) -> 1.625
A7: 430015091 | B7: ADOCANTE SWEET NATURAL LIQUIDO LINEA 25ML | C7: 12 | D7: 12 | E7: 13 | F7: 14 | G7: 14 | H7: 15 | I7: 16 | J7: 16 | K7: 16 | L7: 16 | M7: 23 | N7: 12 | O7: 0 | P7: =IFERROR(VLOOKUP(A7,'[1]Padronização 43'!$B:$Q,16,0),0) -> 0 | Q7: =IFERROR(I7/P7,0) -> 0 | R7: =IFERROR(J7/$P$2,0) -> 0.66666667 | S7: =IFERROR(K7/$P$2,0) -> 0.66666667
A8: 430015092 | B8: ADOCANTE SWEET NATURAL LIQUIDO LINEA 60ML | C8: 27 | D8: 27 | E8: 31 | F8: 33 | G8: 33 | H8: 36 | I8: 36 | J8: 36 | K8: 38 | L8: 38 | M8: 54 | N8: 28 | O8: 0 | P8: =IFERROR(VLOOKUP(A8,'[1]Padronização 43'!$B:$Q,16,0),0) -> 0 | Q8: =IFERROR(I8/P8,0) -> 0 | R8: =IFERROR(J8/$P$2,0) -> 1.5 | S8: =IFERROR(K8/$P$2,0) -> 1.5833333
A9: 430015592 | B9: ADOCANTE XILITOL LIQUIDO LINEA 60ML | C9: 387 | D9: 387 | E9: 441 | F9: 476 | G9: 476 | H9: 506 | I9: 518 | J9: 518 | K9: 536 | L9: 536 | M9: 774 | N9: 399 | O9: 410015592 | P9: =IFERROR(VLOOKUP(A9,'[1]Padronização 43'!$B:$Q,16,0),0) -> 12 | Q9: =IFERROR(I9/P9,0) -> 43.166667 | R9: =IFERROR(J9/$P$2,0) -> 21.583333 | S9: =IFERROR(K9/$P$2,0) -> 22.333333
A10: 430020037 | B10: ADOCANTE SUCRALOSE EM PO LINEA 70 SACHES | C10: 43 | D10: 43 | E10: 49 | F10: 53 | G10: 53 | H10: 56 | I10: 57 | J10: 57 | K10: 59 | L10: 59 | M10: 86 | N10: 44 | O10: 410025605 | P10: =IFERROR(VLOOKUP(A10,'[1]Padronização 43'!$B:$Q,16,0),0) -> 24 | Q10: =IFERROR(I10/P10,0) -> 2.375 | R10: =IFERROR(J10/$P$2,0) -> 2.375 | S10: =IFERROR(K10/$P$2,0) -> 2.4583333
A11: 430020057 | B11: ADOCANTE SUCRALOSE EM PO LINEA 100 SACHES | C11: 42 | D11: 42 | E11: 47 | F11: 51 | G11: 51 | H11: 55 | I11: 56 | J11: 56 | K11: 58 | L11: 58 | M11: 83 | N11: 43 | O11: 410025606 | P11: =IFERROR(VLOOKUP(A11,'[1]Padronização 43'!$B:$Q,16,0),0) -> 24 | Q11: =IFERROR(I11/P11,0) -> 2.3333333 | R11: =IFERROR(J11/$P$2,0) -> 2.3333333 | S11: =IFERROR(K11/$P$2,0) -> 2.4166667
A12: 430020079 | B12: ADOC SUCRALOSE INSTIT EM PO LINEA 1000 SACHES | C12: 1 | D12: 1 | E12: 2 | F12: 2 | G12: 2 | H12: 2 | I12: 2 | J12: 2 | K12: 2 | L12: 2 | M12: 3 | N12: 1 | O12: 410025614 | P12: =IFERROR(VLOOKUP(A12,'[1]Padronização 43'!$B:$Q,16,0),0) -> 1 | Q12: =IFERROR(I12/P12,0) -> 2 | R12: =IFERROR(J12/$P$2,0) -> 0.083333333 | S12: =IFERROR(K12/$P$2,0) -> 0.083333333
A13: 430020080 | B13: ADOC SUCRALOSE INSTIT EM PO LINEA 500 SACHES | C13: 21 | D13: 21 | E13: 24 | F13: 26 | G13: 26 | H13: 28 | I13: 28 | J13: 28 | K13: 29 | L13: 29 | M13: 42 | N13: 22 | O13: 410025615 | P13: =IFERROR(VLOOKUP(A13,'[1]Padronização 43'!$B:$Q,16,0),0) -> 1 | Q13: =IFERROR(I13/P13,0) -> 28 | R13: =IFERROR(J13/$P$2,0) -> 1.1666667 | S13: =IFERROR(K13/$P$2,0) -> 1.2083333
... A158: 430436125 | B158: PIPOCA PRONTA LINEA SABOR CARAMELO 50G | C158: 179 | D158: 179 | E158: 204 | F158: 221 | G158: 221 | H158: 235 | I158: 240 | J158: 240 | K158: 249 | L158: 249 | M158: 359 | N158: 185 | O158: 410436125 | P158: =IFERROR(VLOOKUP(A158,'[1]Padronização 43'!$B:$Q,16,0),0) -> 12 | Q158: =IFERROR(I158/P158,0) -> 20 | R158: =IFERROR(J158/$P$2,0) -> 10 | S158: =IFERROR(K158/$P$2,0) -> 10.375

Sheet Cadastro
A1: PRODUTO | B1: BU | C1: CATEGORIA | D1: SEGMENTO | E1: 2026 | F1: 2025 | G1: 2024 | H1: 2023 | I1: 2022
A2: 400010032 | B2: ADOÇANTES | C2: SUCRALOSE | D2: SUCRALOSE LÍQUIDO | E2: AA | F2: A | G2: A | H2: A | I2: A
A3: 410010020 | B3: ADOÇANTES | C3: SUCRALOSE | D3: SUCRALOSE LÍQUIDO | E3: AA | F3: A | G3: A | H3: A | I3: A
A4: 410010021 | B4: ADOÇANTES | C4: SUCRALOSE | D4: SUCRALOSE LÍQUIDO | E4: AA | F4: A | G4: A | H4: A | I4: A
A5: 410014791 | B5: ADOÇANTES | C5: STEVIA | D5: STEVIA LÍQUIDO | E5: AA | F5: A | G5: A | H5: A | I5: A
A6: 410014792 | B6: ADOÇANTES | C6: STEVIA | D6: STEVIA LÍQUIDO | E6: AA | F6: A | G6: A | H6: A | I6: A
A7: 410015592 | B7: ADOÇANTES | C7: XILITOL | D7: XILITOL LÍQUIDO | E7: AA | F7: A | G7: LANÇAMENTO | H7: LANÇAMENTO | I7: LANÇAMENTO
A8: 410025604 | B8: ADOÇANTES | C8: SUCRALOSE | D8: SUCRALOSE PÓ | E8: AA | F8: A | G8: A | H8: A | I8: DESCONTINUADO
A9: 410025614 | B9: ADOÇANTES | C9: SUCRALOSE | D9: SUCRALOSE INSTITUCIONAL | E9: AA | F9: C | G9: C | H9: C | I9: DESCONTINUADO
A10: 410025626 | B10: ADOÇANTES | C10: SUCRALOSE | D10: SUCRALOSE PÓ | E10: AA | F10: A | G10: A | H10: A | I10: DESCONTINUADO
A11: 410026410 | B11: ADOÇANTES | C11: STEVIA | D11: STEVIA PÓ | E11: AA | F11: A | G11: A | H11: A | I11: DESCONTINUADO
A12: 410080024 | B12: ADOÇANTES | C12: SUCRALOSE | D12: SUCRALOSE CULINÁRIO | E12: AA | F12: A | G12: A | H12: A | I12: A
A13: 415014749 | B13: ADOÇANTES | C13: STEVIA | D13: STEVIA LÍQUIDO | E13: AA | F13: A | G13: A | H13: A | I13: A
... A200: 410026710 | B200: ADOÇANTES | C200: STEVIA | D200: STEVIA PÓ | E200: DESCONTINUADO | F200: DESCONTINUADO | G200: DESCONTINUADO | H200: DESCONTINUADO | I200: DESCONTINUADO
A201: 410030501 | B201: ALIMENTOS | C201: BARRAS | E201: DESCONTINUADO | F201: DESCONTINUADO | G201: DESCONTINUADO | H201: DESCONTINUADO | I201: DESCONTINUADO
A202: 410030503 | B202: ALIMENTOS | C202: BARRAS | E202: DESCONTINUADO | F202: DESCONTINUADO | G202: DESCONTINUADO | H202: DESCONTINUADO | I202: DESCONTINUADO
A203: 410041547 | B203: ALIMENTOS | C203: GELEIAS | D203: GELEIA DE FRUTAS | E203: DESCONTINUADO | F203: DESCONTINUADO | G203: DESCONTINUADO | H203: DESCONTINUADO | I203: DESCONTINUADO
A204: 410042947 | B204: ALIMENTOS | C204: GELEIAS | D204: GELEIA DE FRUTAS | E204: DESCONTINUADO | F204: DESCONTINUADO | G204: DESCONTINUADO | H204: DESCONTINUADO | I204: DESCONTINUADO
A205: 410050010 | B205: ALIMENTOS | C205: OUTROS | E205: DESCONTINUADO | F205: DESCONTINUADO | G205: DESCONTINUADO | H205: DESCONTINUADO | I205: DESCONTINUADO
A206: 410060101 | B206: ALIMENTOS | C206: SHAKE | D206: SHAKE | E206: DESCONTINUADO | F206: DESCONTINUADO | G206: DESCONTINUADO | H206: DESCONTINUADO | I206: DESCONTINUADO
A207: 410060102 | B207: ALIMENTOS | C207: SHAKE | D207: SHAKE | E207: DESCONTINUADO | F207: DESCONTINUADO | G207: DESCONTINUADO | H207: DESCONTINUADO | I207: DESCONTINUADO
A208: 410060201 | B208: ALIMENTOS | C208: SHAKE | D208: SHAKE | E208: DESCONTINUADO | F208: DESCONTINUADO | G208: DESCONTINUADO | H208: DESCONTINUADO | I208: DESCONTINUADO
A209: 410060301 | B209: ALIMENTOS | C209: SHAKE | D209: SHAKE | E209: DESCONTINUADO | F209: DESCONTINUADO | G209: DESCONTINUADO | H209: DESCONTINUADO | I209: DESCONTINUADO
A210: 410060302 | B210: ALIMENTOS | C210: SHAKE | D210: SHAKE | E210: DESCONTINUADO | F210: DESCONTINUADO | G210: DESCONTINUADO | H210: DESCONTINUADO | I210: DESCONTINUADO
A211: 410060406 | B211: ALIMENTOS | C211: SHAKE | D211: SHAKE | E211: DESCONTINUADO | F211: DESCONTINUADO | G211: DESCONTINUADO | H211: DESCONTINUADO | I211: DESCONTINUADO
A212: 410075505 | B212: ALIMENTOS | C212: BEBIDAS EM PÓ | D212: CAPPUCCINO | E212: DESCONTINUADO | F212: DESCONTINUADO | G212: DESCONTINUADO | H212: DESCONTINUADO | I212: DESCONTINUADO
A213: 410080100 | B213: ADOÇANTES | C213: STEVIA | D213: STEVIA CULINÁRIO | E213: DESCONTINUADO | F213: DESCONTINUADO | G213: DESCONTINUADO | H213: DESCONTINUADO | I213: DESCONTINUADO
A214: 410090202 | B214: ALIMENTOS | C214: BEBIDAS EM PÓ | D214: ACHOCOLATADO | E214: DESCONTINUADO | F214: DESCONTINUADO | G214: DESCONTINUADO | H214: DESCONTINUADO | I214: C
A215: 410090206 | B215: ALIMENTOS | C215: BEBIDAS EM PÓ | D215: ACHOCOLATADO | E215: DESCONTINUADO | F215: DESCONTINUADO | G215: DESCONTINUADO | H215: DESCONTINUADO | I215: DESCONTINUADO
A216: 410121102 | B216: ALIMENTOS | C216: BISCOITOS | D216: WAFER | E216: DESCONTINUADO | F216: DESCONTINUADO | G216: DESCONTINUADO | H216: DESCONTINUADO | I216: LANÇAMENTO
A217: 410121302 | B217: ALIMENTOS | C217: BISCOITOS | D217: WAFER | E217: DESCONTINUADO | F217: DESCONTINUADO | G217: DESCONTINUADO | H217: DESCONTINUADO | I217: LANÇAMENTO
... A453: 430436125 | B453: ECOMMERCE | C453: ECOMMERCE | D453: ECOMMERCE | E453: ECOMMERCE | F453: DESCONTINUADO | G453: DESCONTINUADO | H453: DESCONTINUADO | I453: DESCONTINUADO
A454: 440014791 | B454: ADOÇANTES | C454: STEVIA | E454: EXPORTAÇÃO | F454: DESCONTINUADO | G454: DESCONTINUADO | H454: DESCONTINUADO | I454: DESCONTINUADO
A455: 440014792 | B455: ADOÇANTES | C455: STEVIA | E455: EXPORTAÇÃO | F455: DESCONTINUADO | G455: DESCONTINUADO | H455: DESCONTINUADO | I455: DESCONTINUADO
A456: 440015592 | B456: ADOÇANTES | C456: XILITOL | E456: EXPORTAÇÃO | F456: DESCONTINUADO | G456: DESCONTINUADO | H456: DESCONTINUADO | I456: DESCONTINUADO
A457: 440025615 | B457: ADOÇANTES | C457: SUCRALOSE | E457: EXPORTAÇÃO | F457: DESCONTINUADO | G457: DESCONTINUADO | H457: DESCONTINUADO | I457: DESCONTINUADO
A458: 440026208 | B458: ADOÇANTES | C458: XILITOL | E458: EXPORTAÇÃO | F458: DESCONTINUADO | G458: DESCONTINUADO | H458: DESCONTINUADO | I458: DESCONTINUADO
A459: 440026410 | B459: ADOÇANTES | C459: STEVIA | E459: EXPORTAÇÃO | F459: DESCONTINUADO | G459: DESCONTINUADO | H459: DESCONTINUADO | I459: DESCONTINUADO
A460: 440026415 | B460: ADOÇANTES | C460: STEVIA | E460: EXPORTAÇÃO | F460: DESCONTINUADO | G460: DESCONTINUADO | H460: DESCONTINUADO | I460: DESCONTINUADO
A461: 440040157 | B461: ALIMENTOS | C461: GELEIAS | E461: EXPORTAÇÃO | F461: DESCONTINUADO | G461: DESCONTINUADO | H461: DESCONTINUADO | I461: DESCONTINUADO
...

Sheet PMV
A1: PRODUTO | B1: Descrição | C1: QT Pedido | D1: VL Pedido | E1: PMV
A2: 400010032 | B2: LINEA ADOC SUCRAL LIQ PCK (2 75ml+1 25ml)X11 | C2: 5567 | D2: 940798.32 | E2: 168.99557
A3: 410010020 | B3: LINEA ADOC SUCRAL LIQ 24X25ml | C3: 5664 | D3: 572488.57 | E3: 101.07496
A4: 410010021 | B4: LINEA ADOC SUCRAL LIQ 24X75ml | C4: 9710 | D4: 1894107.6 | E4: 195.06773
A5: 410014749 | B5: LINEA ADOC STEVIA LIQ 6X2X60ML | C5: 5 | D5: 462 | E5: 92.4
A6: 410014791 | B6: LINEA ADOC STEVIA LIQ 12X25ml | C6: 7683 | D6: 362102.86 | E6: 47.1304
A7: 410014792 | B7: LINEA ADOC STEVIA LIQ 12X60ml | C7: 14212 | D7: 1389525.1 | E7: 97.771259
A8: 410015592 | B8: LINEA ADOC XILITOL LIQ 12X60ml | C8: 1641 | D8: 210992.65 | E8: 128.57566
A9: 410015602 | B9: LINEA ADOC SUCRAL LIQ 12X2X75ML | C9: 3 | D9: 613.08 | E9: 204.36
A10: 410015618 | B10: LINEA ADOC SUCRAL LIQ INSTIT 6X75ml | C10: 1049 | D10: 38257.43 | E10: 36.470381
A11: 410015729 | B11: LINEA ADOC SACARINA LIQ 12X100ml | C11: 24531 | D11: 1400221.2 | E11: 57.079665
A12: 410020009 | B12: LINEA ADOC SUCRAL PO 24X50X0,8G | C12: 5 | D12: 748.8 | E12: 149.76
A13: 410025604 | B13: LINEA ADOC SUCRAL PO 24X50X0,5g | C13: 3596 | D13: 593119.41 | E13: 164.93866
... A153: 430316999 | B153: MINI CHOC LINEA COOKIES'N CREAM 15 UNID 13g | C153: 72 | D153: 2334.96 | E153: 32.43
